Traceback (most recent call last):
  File "/opt/conda/lib/python3.7/site-packages/jupyter_cache/executors/utils.py", line 56, in single_nb_execution
    record_timing=False,
  File "/opt/conda/lib/python3.7/site-packages/nbclient/client.py", line 1112, in execute
    return NotebookClient(nb=nb, resources=resources, km=km, **kwargs).execute()
  File "/opt/conda/lib/python3.7/site-packages/nbclient/util.py", line 74, in wrapped
    return just_run(coro(*args, **kwargs))
  File "/opt/conda/lib/python3.7/site-packages/nbclient/util.py", line 53, in just_run
    return loop.run_until_complete(coro)
  File "/opt/conda/lib/python3.7/asyncio/base_events.py", line 587, in run_until_complete
    return future.result()
  File "/opt/conda/lib/python3.7/site-packages/nbclient/client.py", line 554, in async_execute
    cell, index, execution_count=self.code_cells_executed + 1
  File "/opt/conda/lib/python3.7/site-packages/nbclient/client.py", line 857, in async_execute_cell
    self._check_raise_for_error(cell, exec_reply)
  File "/opt/conda/lib/python3.7/site-packages/nbclient/client.py", line 760, in _check_raise_for_error
    raise CellExecutionError.from_cell_and_msg(cell, exec_reply_content)
nbclient.exceptions.CellExecutionError: An error occurred while executing the following cell:
------------------
metrics = []
torch.manual_seed(0)

for k in [1,2,4,8,16,32,64]:
    model = DummyModel(data_list[0].x.shape[-1],32,data_list[0].y.shape[-1],k).cuda()
    metrics.append(train_loop(model,train_loader,test_loader,150,lr=1e-2,
                             metric_func = RMSE, loss_func = MAE))
    torch.cuda.empty_cache()
------------------

[0;31m---------------------------------------------------------------------------[0m
[0;31mNameError[0m                                 Traceback (most recent call last)
[0;32m<ipython-input-5-c174548e013c>[0m in [0;36m<module>[0;34m[0m
[1;32m      3[0m [0;34m[0m[0m
[1;32m      4[0m [0;32mfor[0m [0mk[0m [0;32min[0m [0;34m[[0m[0;36m1[0m[0;34m,[0m[0;36m2[0m[0;34m,[0m[0;36m4[0m[0;34m,[0m[0;36m8[0m[0;34m,[0m[0;36m16[0m[0;34m,[0m[0;36m32[0m[0;34m,[0m[0;36m64[0m[0;34m][0m[0;34m:[0m[0;34m[0m[0;34m[0m[0m
[0;32m----> 5[0;31m     [0mmodel[0m [0;34m=[0m [0mDummyModel[0m[0;34m([0m[0mdata_list[0m[0;34m[[0m[0;36m0[0m[0;34m][0m[0;34m.[0m[0mx[0m[0;34m.[0m[0mshape[0m[0;34m[[0m[0;34m-[0m[0;36m1[0m[0;34m][0m[0;34m,[0m[0;36m32[0m[0;34m,[0m[0mdata_list[0m[0;34m[[0m[0;36m0[0m[0;34m][0m[0;34m.[0m[0my[0m[0;34m.[0m[0mshape[0m[0;34m[[0m[0;34m-[0m[0;36m1[0m[0;34m][0m[0;34m,[0m[0mk[0m[0;34m)[0m[0;34m.[0m[0mcuda[0m[0;34m([0m[0;34m)[0m[0;34m[0m[0;34m[0m[0m
[0m[1;32m      6[0m     metrics.append(train_loop(model,train_loader,test_loader,150,lr=1e-2,
[1;32m      7[0m                              metric_func = RMSE, loss_func = MAE))

[0;31mNameError[0m: name 'data_list' is not defined
NameError: name 'data_list' is not defined

